<mujoco model="base">
  <compiler angle="radian" meshdir="meshes/" />
  <option cone="elliptic" impratio="20" />
  <size nconmax="5000" njmax="5000" />

  <asset>
  <texture builtin="gradient" height="256" rgb1=".9 .9 1." rgb2=".2 .3 .4" type="skybox" width="256" />
    <texture builtin="checker" height="512" name="texplane" rgb1=".2 .3 .4" rgb2=".1 0.15 0.2" type="2d" width="512" />
    <texture file="/human_guided_exploration/hem/robosuite/arena/assets/textures/light-wood.png" name="tex-light-wood" type="2d" />
    <texture file="/human_guided_exploration/hem/robosuite/arena/assets/textures/dark-wood.png" name="tex-dark-wood" type="2d" />
    <material name="light-wood" reflectance="0.5" texrepeat="15 15" texture="tex-light-wood" texuniform="true" />
    <material name="dark-wood" reflectance="0.5" texrepeat="5 5" texture="tex-dark-wood" texuniform="true" />
    <material name="floorplane" reflectance="0.5" texrepeat="1 1" texture="texplane" texuniform="true" />
  <mesh file="/robosuite/robosuite/models/assets/robots/panda/meshes/link0.stl" name="link0" />
        <mesh file="/robosuite/robosuite/models/assets/robots/panda/meshes/link1.stl" name="link1" />
        <mesh file="/robosuite/robosuite/models/assets/robots/panda/meshes/link2.stl" name="link2" />
        <mesh file="/robosuite/robosuite/models/assets/robots/panda/meshes/link3.stl" name="link3" />
        <mesh file="/robosuite/robosuite/models/assets/robots/panda/meshes/link4.stl" name="link4" />
        <mesh file="/robosuite/robosuite/models/assets/robots/panda/meshes/link5.stl" name="link5" />
        <mesh file="/robosuite/robosuite/models/assets/robots/panda/meshes/link6.stl" name="link6" />
        <mesh file="/robosuite/robosuite/models/assets/robots/panda/meshes/link7.stl" name="link7" />
        <mesh file="/robosuite/robosuite/models/assets/robots/panda/meshes/link0_vis.stl" name="link0_vis" />
        <mesh file="/robosuite/robosuite/models/assets/robots/panda/meshes/link1_vis.stl" name="link1_vis" />
        <mesh file="/robosuite/robosuite/models/assets/robots/panda/meshes/link2_vis.stl" name="link2_vis" />
        <mesh file="/robosuite/robosuite/models/assets/robots/panda/meshes/link3_vis.stl" name="link3_vis" />
        <mesh file="/robosuite/robosuite/models/assets/robots/panda/meshes/link4_vis.stl" name="link4_vis" />
        <mesh file="/robosuite/robosuite/models/assets/robots/panda/meshes/link5_vis.stl" name="link5_vis" />
        <mesh file="/robosuite/robosuite/models/assets/robots/panda/meshes/link6_vis.stl" name="link6_vis" />
        <mesh file="/robosuite/robosuite/models/assets/robots/panda/meshes/link7_vis.stl" name="link7_vis" />
        <mesh file="/robosuite/robosuite/models/assets/robots/panda/meshes/pedestal.stl" name="pedestal" />
    <mesh file="/robosuite/robosuite/models/assets/grippers/meshes/panda_gripper/hand.stl" name="hand" />

        <mesh file="/robosuite/robosuite/models/assets/grippers/meshes/panda_gripper/hand_vis.stl" name="hand_vis" />
        <mesh file="/robosuite/robosuite/models/assets/grippers/meshes/panda_gripper/finger.stl" name="finger" />
        <mesh file="/robosuite/robosuite/models/assets/grippers/meshes/panda_gripper/finger_vis.stl" name="finger_vis" />
        <mesh file="/robosuite/robosuite/models/assets/grippers/meshes/panda_gripper/finger_longer.stl" name="finger_vis2" />

    <mesh file="/robosuite/robosuite/models/assets/objects/meshes/milk.stl" name="milk_mesh" scale="0.9 0.9 0.9" />
    <texture file="/robosuite/robosuite/models/assets/objects/../textures/ceramic.png" name="tex-ceramic" />
    <material name="ceramic" reflectance="0.5" texrepeat="1 1" texture="tex-ceramic" texuniform="true" />
  <mesh file="/robosuite/robosuite/models/assets/objects/meshes/bread.stl" name="bread_mesh" scale="0.8 0.8 0.8" />
    <texture file="/robosuite/robosuite/models/assets/objects/../textures/bread.png" name="tex-bread" type="2d" />
    <material name="bread" reflectance="0.7" texrepeat="15 15" texture="tex-bread" texuniform="true" />
  <mesh file="/robosuite/robosuite/models/assets/objects/meshes/cereal.stl" name="cereal_mesh" scale="0.4 1.0 0.4" />
    <texture file="/robosuite/robosuite/models/assets/objects/../textures/cereal.png" name="tex-cereal" rgb1="1 1 1" type="cube" />
    <material name="cereal" reflectance="0.5" texrepeat="3 3" texture="tex-cereal" texuniform="false" />
  <mesh file="/robosuite/robosuite/models/assets/objects/meshes/can.stl" name="can_mesh" />
    <texture file="/robosuite/robosuite/models/assets/objects/../textures/can.png" name="tex-can" />
    <material name="coke" reflectance="0.7" texrepeat="5 5" texture="tex-can" texuniform="true" />
  </asset>

  <actuator>
  <velocity ctrllimited="true" ctrlrange="-2.1750 2.1750" joint="joint1" kv="40.0" name="vel_right_j1" /> 
        <velocity ctrllimited="true" ctrlrange="-2.1750 2.1750" joint="joint2" kv="40.0" name="vel_right_j2" /> 
        <velocity ctrllimited="true" ctrlrange="-2.1750 2.1750" joint="joint3" kv="40.0" name="vel_right_j3" /> 
        <velocity ctrllimited="true" ctrlrange="-2.1750 2.1750" joint="joint4" kv="40.0" name="vel_right_j4" /> 
        <velocity ctrllimited="true" ctrlrange="-2.6100 2.6100" joint="joint5" kv="40.0" name="vel_right_j5" /> 
        <velocity ctrllimited="true" ctrlrange="-2.6100 2.6100" joint="joint6" kv="40.0" name="vel_right_j6" /> 
        <velocity ctrllimited="true" ctrlrange="-2.6100 2.6100" joint="joint7" kv="40.0" name="vel_right_j7" /> 
    <position ctrllimited="true" ctrlrange="0.0 0.04" forcelimited="true" forcerange="-20 20" joint="finger_joint1" kp="1000000" name="gripper_joint1" />
        <position ctrllimited="true" ctrlrange="-0.04 0.0" forcelimited="true" forcerange="-20 20" joint="finger_joint2" kp="1000000" name="gripper_joint2" />
    </actuator>

  <worldbody>
  <geom condim="3" material="floorplane" name="floor" pos="0.5 -0.3 0.0" size="3 3 .125" type="plane" />
    <geom pos="0.6 0.2 0.7" rgba="0 0 0 0" size="0.5 1 .2" type="plane" />
    <body name="bin1" pos="0.6 -0.15 0.8">
      <geom friction="1 0.005 0.0001" pos="0 0 0" size="0.2 0.25 0.02" type="box" />
      <geom conaffinity="0" contype="0" group="1" material="light-wood" pos="0 0 0" size="0.2 0.25 0.02" type="box" />
        <geom friction="1 0.005 0.0001" pos="0 0.25 0.05" rgba="0 0 1 1" size="0.21 0.01 0.05" type="box" />
        <geom conaffinity="0" contype="0" group="1" material="light-wood" pos="0 0.25 0.05" size="0.21 0.01 0.05" type="box" />
        <geom friction="1 0.005 0.0001" pos="0 -0.25 0.05" rgba="0 0 1 1" size="0.21 0.01 0.05" type="box" />
        <geom conaffinity="0" contype="0" group="1" material="light-wood" pos="0 -0.25 0.05" size="0.21 0.01 0.05" type="box" />
        <geom friction="1 0.005 0.0001" pos="0.2 0 0.05" rgba="0 0 1 1" size="0.01 0.25 0.05" type="box" />
        <geom conaffinity="0" contype="0" group="1" material="light-wood" pos="0.2 0 0.05" size="0.01 0.25 0.05" type="box" />
        <geom friction="1 0.005 0.0001" pos="-0.2 0 0.05" rgba="0 0 1 1" size="0.01 0.25 0.05" type="box" />
        <geom conaffinity="0" contype="0" group="1" material="light-wood" pos="-0.2 0 0.05" size="0.01 0.25 0.05" type="box" />
    </body>
    <body name="bin2" pos="0.6 0.38000000000000006 0.8">
      <geom friction="1 0.005 0.0001" pos="0 0 0" size="0.2 0.25 0.02" type="box" />
      <geom conaffinity="0" contype="0" group="1" material="dark-wood" pos="0 0 0" size="0.2 0.25 0.02" type="box" />
        <geom friction="1 0.005 0.0001" pos="0 0.25 0.05" rgba="1 0 0 1" size="0.21 0.01 0.05" type="box" />
        <geom conaffinity="0" contype="0" group="1" material="dark-wood" pos="0 0.25 0.05" size="0.21 0.01 0.05" type="box" />
        <geom friction="1 0.005 0.0001" pos="0 0 0.05" rgba="1 0 0 1" size="0.2 0.01 0.05" type="box" />
        <geom conaffinity="0" contype="0" group="1" material="dark-wood" pos="0 0 0.05" size="0.2 0.01 0.05" type="box" />
        <geom friction="1 0.005 0.0001" pos="0 -0.25 0.05" rgba="1 0 0 1" size="0.21 0.01 0.05" type="box" />
        <geom conaffinity="0" contype="0" group="1" material="dark-wood" pos="0 -0.25 0.05" size="0.21 0.01 0.05" type="box" />
        <geom friction="1 0.005 0.0001" pos="0.2 0 0.05" rgba="1 0 0 1" size="0.01 0.25 0.05" type="box" />
        <geom conaffinity="0" contype="0" group="1" material="dark-wood" pos="0.2 0 0.05" size="0.01 0.25 0.05" type="box" />
        <geom friction="1 0.005 0.0001" pos="0 0 0.05" rgba="1 0 0 1" size="0.01 0.25 0.05" type="box" />
        <geom conaffinity="0" contype="0" group="1" material="dark-wood" pos="0 0 0.05" size="0.01 0.25 0.05" type="box" />
        <geom friction="1 0.005 0.0001" pos="-0.2 0 0.05" rgba="1 0 0 1" size="0.01 0.25 0.05" type="box" />
        <geom conaffinity="0" contype="0" group="1" material="dark-wood" pos="-0.2 0 0.05" size="0.01 0.25 0.05" type="box" />
    </body>

    <light castshadow="false" diffuse=".8 .8 .8" dir="0 -.15 -1" directional="false" pos="1.5 0.7 4.0" specular="0.3 0.3 0.3" />
    <light castshadow="false" diffuse=".8 .8 .8" dir="0 -.15 -1" directional="false" pos="-2.5 -3.3 4.0" specular="0.3 0.3 0.3" />
    
    <camera euler="3.14 2.0096641371956415  1.5707963267948966" mode="fixed" name="frontview" pos="1.6 0.10000000000000003 1.75" />
    <camera euler="3.14 2.0096641371956415  1.5707963267948966" mode="fixed" name="highpovfront" pos="1.8 0.10000000000000003 1.75" />
    
    <camera mode="fixed" name="birdview" pos="0.3 0.10000000000000003 3.0" quat="0.7071 0 0 0.7071" />
    
    <camera mode="fixed" name="agentview" pos="1.5 0.10000000000000003 1.75" quat="0.653 0.271 0.271 0.653" />
  <body name="link0" pos="0.0 0.0 0.913">
            <body name="base" pos="0 0 0">
                <inertial diaginertia="0 0 0" mass="0" pos="0 0 0" />
                <body name="controller_box" pos="0 0 0">
                    <inertial diaginertia="1.71363 1.27988 0.809981" mass="46.64" pos="-0.325 0 -0.38" />
                    <geom name="controller_box_col" pos="-0.325 0 -0.38" size="0.11 0.2 0.265" type="box" />
                </body>
                <body name="pedestal_feet" pos="0 0 0">
                    <inertial diaginertia="8.16095 9.59375 15.0785" mass="167.09" pos="-0.1225 0 -0.758" />
                    <geom name="pedestal_feet_col" pos="-0.1225 0 -0.758" size="0.385 0.35 0.155" type="box" />
                </body>
                <body name="torso" pos="0 0 0">
                    <inertial diaginertia="1e-08 1e-08 1e-08" mass="0.0001" pos="0 0 0" />
                    <geom conaffinity="0" contype="0" group="1" name="torso_col" rgba="0.2 0.2 0.2 1" size="0.05 0.05 0.05" type="box" />
                </body>
                <body name="pedestal" pos="0 0 0">
                    <inertial diaginertia="6.0869 5.81635 4.20915" mass="60.864" pos="0 0 0" quat="0.659267 -0.259505 -0.260945 0.655692" />
                    <geom conaffinity="0" contype="0" group="1" mesh="pedestal" name="pedestal_col1" pos="0.26 0.345 -0.91488" quat="0.5 0.5 -0.5 -0.5" rgba="0.2 0.2 0.2 1" type="mesh" />
                    <geom name="pedestal_col2" pos="-0.02 0 -0.29" rgba="0.2 0.2 0.2 1" size="0.18 0.31" type="cylinder" />
                </body>
            </body>
            <inertial diaginertia="0.4 0.4 0.4" mass="4" pos="0 0 0.05" />
            <geom conaffinity="0" contype="0" group="1" mesh="link0_vis" name="link0_visual" rgba="1 1 1 1" type="mesh" />
            <geom group="0" mesh="link0" name="link0_collision" type="mesh" />
            <body name="link1" pos="0 0 0.333">
                <inertial diaginertia="0.3 0.3 0.3" mass="3" pos="0 0 -0.07" />
                <joint axis="0 0 1" damping="0.1" limited="true" name="joint1" pos="0 0 0" range="-2.8973 2.8973" />
                <geom conaffinity="0" contype="0" group="1" mesh="link1_vis" name="link1_visual" rgba="1 1 1 1" type="mesh" />
                <geom group="0" mesh="link1" name="link1_collision" type="mesh" />
                <body name="link2" pos="0 0 0" quat="0.707107 -0.707107 0 0">
                    <inertial diaginertia="0.3 0.3 0.3" mass="3" pos="0 -0.1 0" />
                    <joint axis="0 0 1" damping="0.1" limited="true" name="joint2" pos="0 0 0" range="-1.7628 1.7628" />
                    <geom conaffinity="0" contype="0" group="1" mesh="link2_vis" name="link2_visual" rgba="1 1 1 1" type="mesh" />
                    <geom group="0" mesh="link2" name="link2_collision" type="mesh" />
                    <body name="link3" pos="0 -0.316 0" quat="0.707107 0.707107 0 0">
                        <inertial diaginertia="0.2 0.2 0.2" mass="2" pos="0.04 0 -0.05" />
                        <joint axis="0 0 1" damping="0.1" limited="true" name="joint3" pos="0 0 0" range="-2.8973 2.8973" />
                        <geom conaffinity="0" contype="0" group="1" mesh="link3_vis" name="link3_visual" rgba="1 1 1 1" type="mesh" />
                        <geom group="0" mesh="link3" name="link3_collision" type="mesh" />
                        <body name="link4" pos="0.0825 0 0" quat="0.707107 0.707107 0 0">
                            <inertial diaginertia="0.2 0.2 0.2" mass="2" pos="-0.04 0.05 0" />
                            <joint axis="0 0 1" damping="0.1" limited="true" name="joint4" pos="0 0 0" range="-3.0718 -0.0698" />
                            <geom conaffinity="0" contype="0" group="1" mesh="link4_vis" name="link4_visual" rgba="1 1 1 1" type="mesh" />
                            <geom group="0" mesh="link4" name="link4_collision" type="mesh" />
                            <body name="link5" pos="-0.0825 0.384 0" quat="0.707107 -0.707107 0 0">
                                <inertial diaginertia="0.2 0.2 0.2" mass="2" pos="0 0 -0.15" />
                                <joint axis="0 0 1" damping="0.1" limited="true" name="joint5" pos="0 0 0" range="-2.8973 2.8973" />
                                <geom conaffinity="0" contype="0" group="1" mesh="link5_vis" name="link5_visual" rgba="1 1 1 1" type="mesh" />
                                <geom group="0" mesh="link5" name="link5_collision" type="mesh" />
                                <body name="link6" pos="0 0 0" quat="0.707107 0.707107 0 0">
                                    <inertial diaginertia="0.1 0.1 0.1" mass="1.5" pos="0.06 0 0" />
                                    <joint axis="0 0 1" damping="0.01" limited="true" name="joint6" pos="0 0 0" range="-0.0175 3.7525" />
                                    <geom conaffinity="0" contype="0" group="1" mesh="link6_vis" name="link6_visual" rgba="1 1 1 1" type="mesh" />
                                    <geom group="0" mesh="link6" name="link6_collision" type="mesh" />
                                    <body name="link7" pos="0.088 0 0" quat="0.707107 0.707107 0 0">
                                        <inertial diaginertia="0.05 0.05 0.05" mass="0.5" pos="0 0 0.08" />
                                        <joint axis="0 0 1" damping="0.01" limited="true" name="joint7" pos="0 0 0" range="-2.8973 2.8973" />
                                        <geom conaffinity="0" contype="0" group="1" mesh="link7_vis" name="link7_visual" rgba="1 1 1 1" type="mesh" />
                                        <geom group="0" mesh="link7" name="link7_collision" type="mesh" />
                                        
                                        
                                        <body name="right_hand" pos="0 0 0.107" quat="0.924 0 0 0.383">
                                            <inertial diaginertia="0.05 0.05 0.05" mass="0.5" pos="0 0 0" />
                                            
                                            <site group="1" name="ee" pos="0 0 0" rgba="0 0 1 1" size="0.01 0.01 0.01" type="sphere" />
                                            <site group="1" name="ee_x" pos="0 0 0" quat="0.707105 0.707108 0 0 " rgba="1 0 0 0" size="0.005 .1" type="cylinder" />
                                            <site group="1" name="ee_z" pos="0 0 0" quat="0.707105 0 0 0.707108" rgba="0 0 1 0" size="0.005 .1" type="cylinder" />
                                            <site group="1" name="ee_y" pos="0 0 0" quat="0.707105 0 0.707108 0 " rgba="0 1 0 0" size="0.005 .1" type="cylinder" />
                                        <body name="right_gripper" pos="0 0 -0.018">

            <site group="1" name="ft_frame" pos="0 0 0" rgba="1 0 0 1" size="0.01 0.01 0.01" type="sphere" />

            <inertial diaginertia="0.09 0.07 0.05" mass="0.0" pos="0 0 0.17" quat="0.707107 0.707107 0 0" />
            
      

                  
            <geom conaffinity="0" contype="0" group="1" mesh="hand_vis" name="hand_visual" pos="0 0 0." quat="0.707107 0 0 0.707" rgba="1 1 1 1" type="mesh" />


            <geom group="0" mesh="hand" name="hand_collision" pos="0 0 0." quat="0.707107 0 0 0.707" type="mesh" />

            
            <site group="1" name="grip_site" pos="0 0 0.1050" rgba="0 0 0 0" size="0.01 0.01 0.01" type="sphere" />
            
            <site group="1" name="grip_site_cylinder" pos="0 0 0.1399" rgba="0 0 0 0" size="0.005 10" type="cylinder" />


            <body name="leftfinger" pos="0 0 0.0524" quat="0.707107 0 0 0.70">
                <inertial diaginertia="0.01 0.01 0.005" mass="0.1" pos="0 0 0.05" />
                <joint axis="0 1 0" damping="100" limited="true" name="finger_joint1" pos="0 0 0" range="0.0 0.04" type="slide" />
                <geom conaffinity="0" contype="0" group="1" mesh="finger_vis" name="finger1_visual" quat="0.707107 0.707107 0 0" type="mesh" />

                
                
                
                <geom conaffinity="1" condim="4" contype="0" friction="1 0.005 0.0001" mesh="finger" name="finger1_collision" solref="0.02 1" type="mesh" />
                <body name="finger_joint1_tip" pos="0 0.0085 0.056">
                    <inertial diaginertia="0.01 0.01 0.01" mass="0.01" pos="0 0 0" quat="0 0 0 1" />
                    <geom conaffinity="1" contype="1" friction="2 0.05 0.0001" name="finger1_tip_collision" pos="0 -0.005 -0.015" quat="0 0 0 1" size="0.008 0.004 0.008" solref="0.01 0.5" type="box" />
                </body>
            </body>
            <body name="rightfinger" pos="0 0 0.0524" quat="0.707107 0 0 0.70">
                <inertial diaginertia="0.01 0.01 0.005" mass="0.1" pos="0 0 0.05" />
                <joint axis="0 1 0" damping="100" limited="true" name="finger_joint2" pos="0 0 0" range="-0.04 0.0" type="slide" />
                <geom conaffinity="0" contype="0" group="1" mesh="finger_vis" name="finger2_visual" quat="0 0 0.707107 0.707107" type="mesh" />

                
                
                
                <geom conaffinity="1" condim="4" contype="0" friction="1 0.005 0.0001" mesh="finger" name="finger2_collision" quat="0 0 0 1" solref="0.02 1" type="mesh" />
                <body name="finger_joint2_tip" pos="0 -0.0085 0.056">
                    <inertial diaginertia="0.01 0.01 0.01" mass="0.01" pos="0 0 0" quat="0 0 0 1" />
                    <geom conaffinity="1" contype="1" friction="2 0.05 0.0001" name="finger2_tip_collision" pos="0 0.005 -0.015" quat="0 0 0 1" size="0.008 0.004 0.008" solref="0.01 0.5" type="box" />
                </body>
            </body>
        </body>
    </body>
                                    </body>
                                </body>
                            </body>
                        </body>
                    </body>
                </body>
            </body>
        </body>
    <body name="Milk0" pos="0.5647040596982466 -0.12448420407281016 0.885" quat="-0.7450095532491006 0 0 0.6670537951076926">
        <geom condim="4" density="100" friction="0.95 0.3 0.1" group="1" material="ceramic" mesh="milk_mesh" name="Milk0" pos="0 0 0" solimp="0.998 0.998 0.001" solref="0.001 1" type="mesh" />
      <site name="Milk0" pos="0 0 0" rgba="1 0 0 0" size="0.002 0.002 0.002" type="sphere" /><joint damping="0.0005" name="Milk0" type="free" /></body>
      <body name="Bread0" pos="0.5829235238593896 -0.2928481431760769 0.8450000000000001" quat="0.5350027116223112 0 0 0.8448503409224466">
        <geom condim="4" density="50" friction="0.95 0.3 0.1" group="1" material="bread" mesh="bread_mesh" name="Bread0" pos="0 0 0" solimp="0.998 0.998 0.001" solref="0.001 1" type="mesh" />
      <site name="Bread0" pos="0 0 0" rgba="1 0 0 0" size="0.002 0.002 0.002" type="sphere" /><joint damping="0.0005" name="Bread0" type="free" /></body>
      <body name="Cereal0" pos="0.5227164551643912 -0.19189310292935122 0.8500000000000001" quat="0.4290220336419915 0 0 0.9032940244735874">
        <geom condim="4" density="150" friction="0.95 0.3 0.1" group="1" material="cereal" mesh="cereal_mesh" name="Cereal0" pos="0 0 0" solimp="0.998 0.998 0.001" solref="0.001 1" type="mesh" />
      <site name="Cereal0" pos="0 0 0" rgba="1 0 0 0" size="0.002 0.002 0.002" type="sphere" /><joint damping="0.0005" name="Cereal0" type="free" /></body>
      <body name="Can0" pos="0.6577862844408351 -0.10739396521009795 0.8600000000000001" quat="0.7732954973743503 0 0 0.6340457978258007">
        <geom condim="4" density="100" friction="0.95 0.3 0.1" group="1" material="coke" mesh="can_mesh" name="Can0" pos="0 0 0" solimp="0.998 0.998 0.001" solref="0.001 1" type="mesh" />
      <site name="Can0" pos="0 0 0" rgba="1 0 0 0" size="0.002 0.002 0.002" type="sphere" /><joint damping="0.0005" name="Can0" type="free" /></body>
      </worldbody>

  <equality>
  </equality>
<contact /><default /></mujoco>